
Loading components for TIF035

Traceback (most recent call last):
  File "./bulkAl.py", line 31, in <module>
    energy = bulk.get_potential_energy()
  File "/beda/sw/apps/ase/r2828/lib/python2.6/site-packages/ase/atoms.py", line 627, in get_potential_energy
    return self._calc.get_potential_energy(self)
  File "/beda/sw/apps/GPAW/r9737-py26-i111-mkl102/lib/python2.6/site-packages/gpaw/aseinterface.py", line 38, in get_potential_energy
    self.calculate(atoms, converge=True)
  File "/beda/sw/apps/GPAW/r9737-py26-i111-mkl102/lib/python2.6/site-packages/gpaw/paw.py", line 229, in calculate
    self.initialize(atoms)
  File "/beda/sw/apps/GPAW/r9737-py26-i111-mkl102/lib/python2.6/site-packages/gpaw/paw.py", line 428, in initialize
    kd.set_symmetry(atoms, setups, magmom_av, par.usesymm, N_c, world)
  File "/beda/sw/apps/GPAW/r9737-py26-i111-mkl102/lib/python2.6/site-packages/gpaw/kpt_descriptor.py", line 151, in set_symmetry
    raise ValueError('K-points can only be used with PBCs!')
ValueError: K-points can only be used with PBCs!
GPAW CLEANUP (node 2): <type 'exceptions.ValueError'> occurred.  Calling MPI_Abort!
Traceback (most recent call last):
  File "./bulkAl.py", line 31, in <module>
    energy = bulk.get_potential_energy()
  File "/beda/sw/apps/ase/r2828/lib/python2.6/site-packages/ase/atoms.py", line 627, in get_potential_energy
    return self._calc.get_potential_energy(self)
  File "/beda/sw/apps/GPAW/r9737-py26-i111-mkl102/lib/python2.6/site-packages/gpaw/aseinterface.py", line 38, in get_potential_energy
    self.calculate(atoms, converge=True)
  File "/beda/sw/apps/GPAW/r9737-py26-i111-mkl102/lib/python2.6/site-packages/gpaw/paw.py", line 229, in calculate
    self.initialize(atoms)
  File "/beda/sw/apps/GPAW/r9737-py26-i111-mkl102/lib/python2.6/site-packages/gpaw/paw.py", line 428, in initialize
    kd.set_symmetry(atoms, setups, magmom_av, par.usesymm, N_c, world)
  File "/beda/sw/apps/GPAW/r9737-py26-i111-mkl102/lib/python2.6/site-packages/gpaw/kpt_descriptor.py", line 151, in set_symmetry
    raise ValueError('K-points can only be used with PBCs!')
ValueError: K-points can only be used with PBCs!
GPAW CLEANUP (node 1): <type 'exceptions.ValueError'> occurred.  Calling MPI_Abort!
Traceback (most recent call last):
  File "./bulkAl.py", line 31, in <module>
    energy = bulk.get_potential_energy()
  File "/beda/sw/apps/ase/r2828/lib/python2.6/site-packages/ase/atoms.py", line 627, in get_potential_energy
    return self._calc.get_potential_energy(self)
  File "/beda/sw/apps/GPAW/r9737-py26-i111-mkl102/lib/python2.6/site-packages/gpaw/aseinterface.py", line 38, in get_potential_energy
    self.calculate(atoms, converge=True)
  File "/beda/sw/apps/GPAW/r9737-py26-i111-mkl102/lib/python2.6/site-packages/gpaw/paw.py", line 229, in calculate
    self.initialize(atoms)
  File "/beda/sw/apps/GPAW/r9737-py26-i111-mkl102/lib/python2.6/site-packages/gpaw/paw.py", line 428, in initialize
    kd.set_symmetry(atoms, setups, magmom_av, par.usesymm, N_c, world)
  File "/beda/sw/apps/GPAW/r9737-py26-i111-mkl102/lib/python2.6/site-packages/gpaw/kpt_descriptor.py", line 151, in set_symmetry
    raise ValueError('K-points can only be used with PBCs!')
ValueError: K-points can only be used with PBCs!
GPAW CLEANUP (node 6): <type 'exceptions.ValueError'> occurred.  Calling MPI_Abort!
Traceback (most recent call last):
  File "./bulkAl.py", line 31, in <module>
    energy = bulk.get_potential_energy()
  File "/beda/sw/apps/ase/r2828/lib/python2.6/site-packages/ase/atoms.py", line 627, in get_potential_energy
    return self._calc.get_potential_energy(self)
  File "/beda/sw/apps/GPAW/r9737-py26-i111-mkl102/lib/python2.6/site-packages/gpaw/aseinterface.py", line 38, in get_potential_energy
    self.calculate(atoms, converge=True)
  File "/beda/sw/apps/GPAW/r9737-py26-i111-mkl102/lib/python2.6/site-packages/gpaw/paw.py", line 229, in calculate
    self.initialize(atoms)
  File "/beda/sw/apps/GPAW/r9737-py26-i111-mkl102/lib/python2.6/site-packages/gpaw/paw.py", line 428, in initialize
    kd.set_symmetry(atoms, setups, magmom_av, par.usesymm, N_c, world)
  File "/beda/sw/apps/GPAW/r9737-py26-i111-mkl102/lib/python2.6/site-packages/gpaw/kpt_descriptor.py", line 151, in set_symmetry
    raise ValueError('K-points can only be used with PBCs!')
ValueError: K-points can only be used with PBCs!
GPAW CLEANUP (node 5): <type 'exceptions.ValueError'> occurred.  Calling MPI_Abort!
Traceback (most recent call last):
  File "./bulkAl.py", line 31, in <module>
    energy = bulk.get_potential_energy()
  File "/beda/sw/apps/ase/r2828/lib/python2.6/site-packages/ase/atoms.py", line 627, in get_potential_energy
    return self._calc.get_potential_energy(self)
  File "/beda/sw/apps/GPAW/r9737-py26-i111-mkl102/lib/python2.6/site-packages/gpaw/aseinterface.py", line 38, in get_potential_energy
    self.calculate(atoms, converge=True)
  File "/beda/sw/apps/GPAW/r9737-py26-i111-mkl102/lib/python2.6/site-packages/gpaw/paw.py", line 229, in calculate
    self.initialize(atoms)
  File "/beda/sw/apps/GPAW/r9737-py26-i111-mkl102/lib/python2.6/site-packages/gpaw/paw.py", line 428, in initialize
    kd.set_symmetry(atoms, setups, magmom_av, par.usesymm, N_c, world)
  File "/beda/sw/apps/GPAW/r9737-py26-i111-mkl102/lib/python2.6/site-packages/gpaw/kpt_descriptor.py", line 151, in set_symmetry
    raise ValueError('K-points can only be used with PBCs!')
ValueError: K-points can only be used with PBCs!
GPAW CLEANUP (node 7): <type 'exceptions.ValueError'> occurred.  Calling MPI_Abort!
Traceback (most recent call last):
  File "./bulkAl.py", line 31, in <module>
    energy = bulk.get_potential_energy()
  File "/beda/sw/apps/ase/r2828/lib/python2.6/site-packages/ase/atoms.py", line 627, in get_potential_energy
    return self._calc.get_potential_energy(self)
  File "/beda/sw/apps/GPAW/r9737-py26-i111-mkl102/lib/python2.6/site-packages/gpaw/aseinterface.py", line 38, in get_potential_energy
    self.calculate(atoms, converge=True)
  File "/beda/sw/apps/GPAW/r9737-py26-i111-mkl102/lib/python2.6/site-packages/gpaw/paw.py", line 229, in calculate
    self.initialize(atoms)
  File "/beda/sw/apps/GPAW/r9737-py26-i111-mkl102/lib/python2.6/site-packages/gpaw/paw.py", line 428, in initialize
    kd.set_symmetry(atoms, setups, magmom_av, par.usesymm, N_c, world)
  File "/beda/sw/apps/GPAW/r9737-py26-i111-mkl102/lib/python2.6/site-packages/gpaw/kpt_descriptor.py", line 151, in set_symmetry
    raise ValueError('K-points can only be used with PBCs!')
ValueError: K-points can only be used with PBCs!
GPAW CLEANUP (node 3): <type 'exceptions.ValueError'> occurred.  Calling MPI_Abort!
Traceback (most recent call last):
  File "./bulkAl.py", line 31, in <module>
    energy = bulk.get_potential_energy()
  File "/beda/sw/apps/ase/r2828/lib/python2.6/site-packages/ase/atoms.py", line 627, in get_potential_energy
    return self._calc.get_potential_energy(self)
  File "/beda/sw/apps/GPAW/r9737-py26-i111-mkl102/lib/python2.6/site-packages/gpaw/aseinterface.py", line 38, in get_potential_energy
    self.calculate(atoms, converge=True)
  File "/beda/sw/apps/GPAW/r9737-py26-i111-mkl102/lib/python2.6/site-packages/gpaw/paw.py", line 229, in calculate
    self.initialize(atoms)
  File "/beda/sw/apps/GPAW/r9737-py26-i111-mkl102/lib/python2.6/site-packages/gpaw/paw.py", line 428, in initialize
    kd.set_symmetry(atoms, setups, magmom_av, par.usesymm, N_c, world)
  File "/beda/sw/apps/GPAW/r9737-py26-i111-mkl102/lib/python2.6/site-packages/gpaw/kpt_descriptor.py", line 151, in set_symmetry
    raise ValueError('K-points can only be used with PBCs!')
ValueError: K-points can only be used with PBCs!
GPAW CLEANUP (node 4): <type 'exceptions.ValueError'> occurred.  Calling MPI_Abort!
Traceback (most recent call last):
  File "./bulkAl.py", line 31, in <module>
    energy = bulk.get_potential_energy()
  File "/beda/sw/apps/ase/r2828/lib/python2.6/site-packages/ase/atoms.py", line 627, in get_potential_energy
    return self._calc.get_potential_energy(self)
  File "/beda/sw/apps/GPAW/r9737-py26-i111-mkl102/lib/python2.6/site-packages/gpaw/aseinterface.py", line 38, in get_potential_energy
    self.calculate(atoms, converge=True)
  File "/beda/sw/apps/GPAW/r9737-py26-i111-mkl102/lib/python2.6/site-packages/gpaw/paw.py", line 229, in calculate
    self.initialize(atoms)
  File "/beda/sw/apps/GPAW/r9737-py26-i111-mkl102/lib/python2.6/site-packages/gpaw/paw.py", line 428, in initialize
    kd.set_symmetry(atoms, setups, magmom_av, par.usesymm, N_c, world)
  File "/beda/sw/apps/GPAW/r9737-py26-i111-mkl102/lib/python2.6/site-packages/gpaw/kpt_descriptor.py", line 151, in set_symmetry
    raise ValueError('K-points can only be used with PBCs!')
ValueError: K-points can only be used with PBCs!
GPAW CLEANUP (node 0): <type 'exceptions.ValueError'> occurred.  Calling MPI_Abort!
--------------------------------------------------------------------------
MPI_ABORT was invoked on rank 2 in communicator MPI_COMM_WORLD 
with errorcode 42.

NOTE: invoking MPI_ABORT causes Open MPI to kill all MPI processes.
You may or may not see output from other processes, depending on
exactly when Open MPI kills them.
--------------------------------------------------------------------------
--------------------------------------------------------------------------
mpirun has exited due to process rank 2 with PID 12633 on
node beda63-2.nfs.private exiting without calling "finalize". This may
have caused other processes in the application to be
terminated by signals sent by mpirun (as reported here).
--------------------------------------------------------------------------
